[2023-11-07 17:39:32,760] {taskinstance.py:1159} INFO - Dependencies all met for <TaskInstance: selenium_dag.test_selenium manual__2023-11-07T17:34:29.739696+00:00 [queued]>
[2023-11-07 17:39:32,772] {taskinstance.py:1159} INFO - Dependencies all met for <TaskInstance: selenium_dag.test_selenium manual__2023-11-07T17:34:29.739696+00:00 [queued]>
[2023-11-07 17:39:32,772] {taskinstance.py:1356} INFO - 
--------------------------------------------------------------------------------
[2023-11-07 17:39:32,772] {taskinstance.py:1357} INFO - Starting attempt 2 of 2
[2023-11-07 17:39:32,772] {taskinstance.py:1358} INFO - 
--------------------------------------------------------------------------------
[2023-11-07 17:39:32,790] {taskinstance.py:1377} INFO - Executing <Task(PythonOperator): test_selenium> on 2023-11-07 17:34:29.739696+00:00
[2023-11-07 17:39:32,796] {standard_task_runner.py:52} INFO - Started process 164 to run task
[2023-11-07 17:39:32,803] {standard_task_runner.py:79} INFO - Running: ['airflow', 'tasks', 'run', 'selenium_dag', 'test_selenium', 'manual__2023-11-07T17:34:29.739696+00:00', '--job-id', '12', '--raw', '--subdir', 'DAGS_FOLDER/test_selinium.py', '--cfg-path', '/tmp/tmp24fw7vv5', '--error-file', '/tmp/tmpskyppxo0']
[2023-11-07 17:39:32,806] {standard_task_runner.py:80} INFO - Job 12: Subtask test_selenium
[2023-11-07 17:39:32,908] {task_command.py:370} INFO - Running <TaskInstance: selenium_dag.test_selenium manual__2023-11-07T17:34:29.739696+00:00 [running]> on host 910bfbe27458
[2023-11-07 17:39:33,034] {taskinstance.py:1569} INFO - Exporting the following env vars:
AIRFLOW_CTX_DAG_OWNER=airflow
AIRFLOW_CTX_DAG_ID=selenium_dag
AIRFLOW_CTX_TASK_ID=test_selenium
AIRFLOW_CTX_EXECUTION_DATE=2023-11-07T17:34:29.739696+00:00
AIRFLOW_CTX_TRY_NUMBER=2
AIRFLOW_CTX_DAG_RUN_ID=manual__2023-11-07T17:34:29.739696+00:00
[2023-11-07 17:39:33,036] {logger.py:11} INFO - ====== WebDriver manager ======
[2023-11-07 17:39:33,507] {logger.py:11} INFO - Get LATEST chromedriver version for chromium
[2023-11-07 17:39:33,589] {logger.py:11} INFO - Get LATEST chromedriver version for chromium
[2023-11-07 17:39:33,644] {logger.py:11} INFO - There is no [linux64] chromedriver "119.0.6045.105" for browser chromium "119.0.6045" in cache
[2023-11-07 17:39:33,645] {logger.py:11} INFO - Get LATEST chromedriver version for chromium
[2023-11-07 17:39:33,753] {logger.py:11} INFO - WebDriver version 119.0.6045.105 selected
[2023-11-07 17:39:33,754] {logger.py:11} INFO - Modern chrome version https://edgedl.me.gvt1.com/edgedl/chrome/chrome-for-testing/119.0.6045.105/linux64/chromedriver-linux64.zip
[2023-11-07 17:39:33,754] {logger.py:11} INFO - About to download new driver from https://edgedl.me.gvt1.com/edgedl/chrome/chrome-for-testing/119.0.6045.105/linux64/chromedriver-linux64.zip
[2023-11-07 17:39:33,810] {logger.py:11} INFO - Driver downloading response is 200
[2023-11-07 17:39:33,935] {logger.py:11} INFO - Get LATEST chromedriver version for chromium
[2023-11-07 17:39:34,225] {logger.py:11} INFO - Driver has been saved in cache [/root/.wdm/drivers/chromedriver/linux64/119.0.6045.105]
[2023-11-07 17:39:34,984] {taskinstance.py:1889} ERROR - Task failed with exception
Traceback (most recent call last):
  File "/root/.cache/pypoetry/virtualenvs/02-dbt-in-airflow-BsnH11MF-py3.8/lib/python3.8/site-packages/airflow/operators/python.py", line 171, in execute
    return_value = self.execute_callable()
  File "/root/.cache/pypoetry/virtualenvs/02-dbt-in-airflow-BsnH11MF-py3.8/lib/python3.8/site-packages/airflow/operators/python.py", line 189, in execute_callable
    return self.python_callable(*self.op_args, **self.op_kwargs)
  File "/app/airflow/dags/test_selinium.py", line 15, in test_selenium_driver
    driver = webdriver.Chrome(service=Service(ChromeDriverManager(chrome_type=ChromeType.CHROMIUM).install()))
  File "/root/.cache/pypoetry/virtualenvs/02-dbt-in-airflow-BsnH11MF-py3.8/lib/python3.8/site-packages/selenium/webdriver/chrome/webdriver.py", line 45, in __init__
    super().__init__(
  File "/root/.cache/pypoetry/virtualenvs/02-dbt-in-airflow-BsnH11MF-py3.8/lib/python3.8/site-packages/selenium/webdriver/chromium/webdriver.py", line 56, in __init__
    super().__init__(
  File "/root/.cache/pypoetry/virtualenvs/02-dbt-in-airflow-BsnH11MF-py3.8/lib/python3.8/site-packages/selenium/webdriver/remote/webdriver.py", line 208, in __init__
    self.start_session(capabilities)
  File "/root/.cache/pypoetry/virtualenvs/02-dbt-in-airflow-BsnH11MF-py3.8/lib/python3.8/site-packages/selenium/webdriver/remote/webdriver.py", line 292, in start_session
    response = self.execute(Command.NEW_SESSION, caps)["value"]
  File "/root/.cache/pypoetry/virtualenvs/02-dbt-in-airflow-BsnH11MF-py3.8/lib/python3.8/site-packages/selenium/webdriver/remote/webdriver.py", line 347, in execute
    self.error_handler.check_response(response)
  File "/root/.cache/pypoetry/virtualenvs/02-dbt-in-airflow-BsnH11MF-py3.8/lib/python3.8/site-packages/selenium/webdriver/remote/errorhandler.py", line 229, in check_response
    raise exception_class(message, screen, stacktrace)
selenium.common.exceptions.SessionNotCreatedException: Message: session not created: Chrome failed to start: exited normally.
  (session not created: DevToolsActivePort file doesn't exist)
  (The process started from chrome location /usr/bin/chromium is no longer running, so ChromeDriver is assuming that Chrome has crashed.)
Stacktrace:
#0 0x55780c6605e3 <unknown>
#1 0x55780c3230b7 <unknown>
#2 0x55780c359e55 <unknown>
#3 0x55780c356b81 <unknown>
#4 0x55780c3a147f <unknown>
#5 0x55780c397cc3 <unknown>
#6 0x55780c3630e4 <unknown>
#7 0x55780c3640ae <unknown>
#8 0x55780c626ce1 <unknown>
#9 0x55780c62ab7e <unknown>
#10 0x55780c6144b5 <unknown>
#11 0x55780c62b7d6 <unknown>
#12 0x55780c5f7dbf <unknown>
#13 0x55780c64e748 <unknown>
#14 0x55780c64e917 <unknown>
#15 0x55780c65f773 <unknown>
#16 0x7fd7ee425ea7 start_thread

[2023-11-07 17:39:35,016] {taskinstance.py:1395} INFO - Marking task as FAILED. dag_id=selenium_dag, task_id=test_selenium, execution_date=20231107T173429, start_date=20231107T173932, end_date=20231107T173935
[2023-11-07 17:39:35,048] {standard_task_runner.py:92} ERROR - Failed to execute job 12 for task test_selenium (Message: session not created: Chrome failed to start: exited normally.
  (session not created: DevToolsActivePort file doesn't exist)
  (The process started from chrome location /usr/bin/chromium is no longer running, so ChromeDriver is assuming that Chrome has crashed.)
Stacktrace:
#0 0x55780c6605e3 <unknown>
#1 0x55780c3230b7 <unknown>
#2 0x55780c359e55 <unknown>
#3 0x55780c356b81 <unknown>
#4 0x55780c3a147f <unknown>
#5 0x55780c397cc3 <unknown>
#6 0x55780c3630e4 <unknown>
#7 0x55780c3640ae <unknown>
#8 0x55780c626ce1 <unknown>
#9 0x55780c62ab7e <unknown>
#10 0x55780c6144b5 <unknown>
#11 0x55780c62b7d6 <unknown>
#12 0x55780c5f7dbf <unknown>
#13 0x55780c64e748 <unknown>
#14 0x55780c64e917 <unknown>
#15 0x55780c65f773 <unknown>
#16 0x7fd7ee425ea7 start_thread
; 164)
[2023-11-07 17:39:35,079] {local_task_job.py:156} INFO - Task exited with return code 1
[2023-11-07 17:39:35,167] {local_task_job.py:273} INFO - 0 downstream tasks scheduled from follow-on schedule check
